package com.chaosmodders.chaosbeasts.worldgen;
import java.util.Random;

import net.minecraft.block.material.Material;
import net.minecraft.init.Blocks;
import net.minecraft.world.World;
import net.minecraft.world.gen.feature.WorldGenerator;

import com.chaosmodders.chaosbeasts.blocks.ChaosBlocks;

public class WorldGenVoidTomb extends WorldGenerator
{


	public WorldGenVoidTomb() { }

	public boolean generate(World world, Random rand, int i, int j, int k) {
		byte b0 = 3;
        int l = rand.nextInt(2) + 2;
        int i1 = rand.nextInt(2) + 2;
        int j1 = 0;
        int k1;
        int l1;
        int i2;

        for (k1 = i - l - 1; k1 <= i + l + 1; ++k1)
        {
            for (l1 = j - 1; l1 <= j + b0 + 1; ++l1)
            {
                for (i2 = k - i1 - 1; i2 <= k + i1 + 1; ++i2)
                {
                    Material material = world.getBlock(k1, l1, i2).getMaterial();

                    if (l1 == j - 1 && !material.isSolid())
                    {
                        return false;
                    }

                    if (l1 == j + b0 + 1 && !material.isSolid())
                    {
                        return false;
                    }

                    if ((k1 == i - l - 1 || k1 == i + l + 1 || i2 == k - i1 - 1 || i2 == k + i1 + 1) && l1 == j && world.isAirBlock(k1, l1, i2) && world.isAirBlock(k1, l1 + 1, i2))
                    {
                        ++j1;
                    }
                }
            }
        }
        
		world.setBlock(i + 0, j + 0, k + 0, Blocks.stone);
		world.setBlock(i + 0, j + 0, k + 1, Blocks.stone);
		world.setBlock(i + 0, j + 0, k + 2, Blocks.stone);
		world.setBlock(i + 0, j + 0, k + 3, Blocks.stone);
		world.setBlock(i + 0, j + 0, k + 4, Blocks.stone);
		world.setBlock(i + 0, j + 0, k + 5, Blocks.stone);
		world.setBlock(i + 0, j + 0, k + 6, Blocks.stone);
		world.setBlock(i + 0, j + 0, k + 7, Blocks.stone);
		world.setBlock(i + 0, j + 0, k + 8, Blocks.stone);
		world.setBlock(i + 0, j + 0, k + 9, Blocks.stone);
		world.setBlock(i + 0, j + 1, k + 0, Blocks.stone);
		world.setBlock(i + 0, j + 1, k + 1, Blocks.stone);
		world.setBlock(i + 0, j + 1, k + 2, Blocks.stone);
		world.setBlock(i + 0, j + 1, k + 3, Blocks.stone);
		world.setBlock(i + 0, j + 1, k + 4, Blocks.stone);
		world.setBlock(i + 0, j + 1, k + 5, Blocks.stone);
		world.setBlock(i + 0, j + 1, k + 6, Blocks.stone);
		world.setBlock(i + 0, j + 1, k + 7, Blocks.stone);
		world.setBlock(i + 0, j + 1, k + 8, Blocks.stone);
		world.setBlock(i + 0, j + 1, k + 9, Blocks.stone);
		world.setBlock(i + 0, j + 2, k + 0, Blocks.stone);
		world.setBlock(i + 0, j + 2, k + 1, Blocks.stone);
		world.setBlock(i + 0, j + 2, k + 2, Blocks.stone);
		world.setBlock(i + 0, j + 2, k + 3, Blocks.stone);
		world.setBlock(i + 0, j + 2, k + 4, Blocks.stone);
		world.setBlock(i + 0, j + 2, k + 5, Blocks.stone);
		world.setBlock(i + 0, j + 2, k + 6, Blocks.stone);
		world.setBlock(i + 0, j + 2, k + 7, Blocks.stone);
		world.setBlock(i + 0, j + 2, k + 8, Blocks.stone);
		world.setBlock(i + 0, j + 2, k + 9, Blocks.stone);
		world.setBlock(i + 0, j + 3, k + 0, Blocks.stone);
		world.setBlock(i + 0, j + 3, k + 1, Blocks.stone);
		world.setBlock(i + 0, j + 3, k + 2, Blocks.stone);
		world.setBlock(i + 0, j + 3, k + 3, Blocks.stone);
		world.setBlock(i + 0, j + 3, k + 4, Blocks.stone);
		world.setBlock(i + 0, j + 3, k + 5, Blocks.stone);
		world.setBlock(i + 0, j + 3, k + 6, Blocks.stone);
		world.setBlock(i + 0, j + 3, k + 7, Blocks.stone);
		world.setBlock(i + 0, j + 3, k + 8, Blocks.stone);
		world.setBlock(i + 0, j + 3, k + 9, Blocks.stone);
		world.setBlock(i + 0, j + 4, k + 0, Blocks.stone);
		world.setBlock(i + 0, j + 4, k + 1, Blocks.stone);
		world.setBlock(i + 0, j + 4, k + 2, Blocks.stone);
		world.setBlock(i + 0, j + 4, k + 3, Blocks.stone);
		world.setBlock(i + 0, j + 4, k + 4, Blocks.stone);
		world.setBlock(i + 0, j + 4, k + 5, Blocks.stone);
		world.setBlock(i + 0, j + 4, k + 6, Blocks.stone);
		world.setBlock(i + 0, j + 4, k + 7, Blocks.stone);
		world.setBlock(i + 0, j + 4, k + 8, Blocks.stone);
		world.setBlock(i + 0, j + 4, k + 9, Blocks.stone);
		world.setBlock(i + 0, j + 5, k + 0, Blocks.stone);
		world.setBlock(i + 0, j + 5, k + 1, Blocks.stone);
		world.setBlock(i + 0, j + 5, k + 2, Blocks.stone);
		world.setBlock(i + 0, j + 5, k + 3, Blocks.stone);
		world.setBlock(i + 0, j + 5, k + 4, Blocks.stone);
		world.setBlock(i + 0, j + 5, k + 5, Blocks.stone);
		world.setBlock(i + 0, j + 5, k + 6, Blocks.stone);
		world.setBlock(i + 0, j + 5, k + 7, Blocks.stone);
		world.setBlock(i + 0, j + 5, k + 8, Blocks.stone);
		world.setBlock(i + 0, j + 5, k + 9, Blocks.stone);
		world.setBlock(i + 0, j + 6, k + 0, Blocks.stone);
		world.setBlock(i + 0, j + 6, k + 1, Blocks.stone);
		world.setBlock(i + 0, j + 6, k + 2, Blocks.stone);
		world.setBlock(i + 0, j + 6, k + 3, Blocks.stone);
		world.setBlock(i + 0, j + 6, k + 4, Blocks.stone);
		world.setBlock(i + 0, j + 6, k + 5, Blocks.stone);
		world.setBlock(i + 0, j + 6, k + 6, Blocks.stone);
		world.setBlock(i + 0, j + 6, k + 7, Blocks.stone);
		world.setBlock(i + 0, j + 6, k + 8, Blocks.stone);
		world.setBlock(i + 0, j + 6, k + 9, Blocks.stone);
		world.setBlock(i + 0, j + 7, k + 0, Blocks.stone);
		world.setBlock(i + 0, j + 7, k + 1, Blocks.stone);
		world.setBlock(i + 0, j + 7, k + 2, Blocks.stone);
		world.setBlock(i + 0, j + 7, k + 3, Blocks.stone);
		world.setBlock(i + 0, j + 7, k + 4, Blocks.stone);
		world.setBlock(i + 0, j + 7, k + 5, Blocks.stone);
		world.setBlock(i + 0, j + 7, k + 6, Blocks.stone);
		world.setBlock(i + 0, j + 7, k + 7, Blocks.stone);
		world.setBlock(i + 0, j + 7, k + 8, Blocks.stone);
		world.setBlock(i + 0, j + 7, k + 9, Blocks.stone);
		world.setBlock(i + 0, j + 8, k + 0, Blocks.stone);
		world.setBlock(i + 0, j + 8, k + 1, Blocks.stone);
		world.setBlock(i + 0, j + 8, k + 2, Blocks.stone);
		world.setBlock(i + 0, j + 8, k + 3, Blocks.stone);
		world.setBlock(i + 0, j + 8, k + 4, Blocks.stone);
		world.setBlock(i + 0, j + 8, k + 5, Blocks.stone);
		world.setBlock(i + 0, j + 8, k + 6, Blocks.stone);
		world.setBlock(i + 0, j + 8, k + 7, Blocks.stone);
		world.setBlock(i + 0, j + 8, k + 8, Blocks.stone);
		world.setBlock(i + 0, j + 8, k + 9, Blocks.stone);
		world.setBlock(i + 0, j + 9, k + 0, Blocks.stone);
		world.setBlock(i + 0, j + 9, k + 1, Blocks.stone);
		world.setBlock(i + 0, j + 9, k + 2, Blocks.stone);
		world.setBlock(i + 0, j + 9, k + 3, Blocks.stone);
		world.setBlock(i + 0, j + 9, k + 4, Blocks.stone);
		world.setBlock(i + 0, j + 9, k + 5, Blocks.stone);
		world.setBlock(i + 0, j + 9, k + 6, Blocks.stone);
		world.setBlock(i + 0, j + 9, k + 7, Blocks.stone);
		world.setBlock(i + 0, j + 9, k + 8, Blocks.stone);
		world.setBlock(i + 0, j + 9, k + 9, Blocks.stone);
		world.setBlock(i + 1, j + 0, k + 0, Blocks.stone);
		world.setBlock(i + 1, j + 0, k + 1, Blocks.stone);
		world.setBlock(i + 1, j + 0, k + 2, Blocks.stone);
		world.setBlock(i + 1, j + 0, k + 3, Blocks.stone);
		world.setBlock(i + 1, j + 0, k + 4, Blocks.stone);
		world.setBlock(i + 1, j + 0, k + 5, Blocks.stone);
		world.setBlock(i + 1, j + 0, k + 6, Blocks.stone);
		world.setBlock(i + 1, j + 0, k + 7, Blocks.stone);
		world.setBlock(i + 1, j + 0, k + 8, Blocks.stone);
		world.setBlock(i + 1, j + 0, k + 9, Blocks.stone);
		world.setBlock(i + 1, j + 1, k + 0, Blocks.stone);
		world.setBlock(i + 1, j + 1, k + 1, Blocks.stone);
		world.setBlock(i + 1, j + 1, k + 2, Blocks.stone);
		world.setBlock(i + 1, j + 1, k + 3, Blocks.stone);
		world.setBlock(i + 1, j + 1, k + 4, Blocks.stone);
		world.setBlock(i + 1, j + 1, k + 5, Blocks.stone);
		world.setBlock(i + 1, j + 1, k + 6, Blocks.stone);
		world.setBlock(i + 1, j + 1, k + 7, Blocks.stone);
		world.setBlock(i + 1, j + 1, k + 8, Blocks.stone);
		world.setBlock(i + 1, j + 1, k + 9, Blocks.stone);
		world.setBlock(i + 1, j + 2, k + 0, Blocks.stone);
		world.setBlock(i + 1, j + 2, k + 1, Blocks.stone);
		world.setBlock(i + 1, j + 2, k + 2, Blocks.stone);
		world.setBlock(i + 1, j + 2, k + 3, Blocks.stone);
		world.setBlock(i + 1, j + 2, k + 6, Blocks.stone);
		world.setBlock(i + 1, j + 2, k + 7, Blocks.stone);
		world.setBlock(i + 1, j + 2, k + 8, Blocks.stone);
		world.setBlock(i + 1, j + 2, k + 9, Blocks.stone);
		world.setBlock(i + 1, j + 3, k + 0, Blocks.stone);
		world.setBlock(i + 1, j + 3, k + 1, Blocks.stone);
		world.setBlock(i + 1, j + 3, k + 2, Blocks.stone);
		world.setBlock(i + 1, j + 3, k + 3, Blocks.stone);
		world.setBlock(i + 1, j + 3, k + 6, Blocks.stone);
		world.setBlock(i + 1, j + 3, k + 7, Blocks.stone);
		world.setBlock(i + 1, j + 3, k + 8, Blocks.stone);
		world.setBlock(i + 1, j + 3, k + 9, Blocks.stone);
		world.setBlock(i + 1, j + 4, k + 0, Blocks.stone);
		world.setBlock(i + 1, j + 4, k + 1, Blocks.stone);
		world.setBlock(i + 1, j + 4, k + 2, Blocks.stone);
		world.setBlock(i + 1, j + 4, k + 3, Blocks.stone);
		world.setBlock(i + 1, j + 4, k + 4, Blocks.stone);
		world.setBlock(i + 1, j + 4, k + 5, Blocks.stone);
		world.setBlock(i + 1, j + 4, k + 6, Blocks.stone);
		world.setBlock(i + 1, j + 4, k + 7, Blocks.stone);
		world.setBlock(i + 1, j + 4, k + 8, Blocks.stone);
		world.setBlock(i + 1, j + 4, k + 9, Blocks.stone);
		world.setBlock(i + 1, j + 5, k + 0, Blocks.stone);
		world.setBlock(i + 1, j + 5, k + 1, Blocks.stone);
		world.setBlock(i + 1, j + 5, k + 2, Blocks.stone);
		world.setBlock(i + 1, j + 5, k + 3, Blocks.stone);
		world.setBlock(i + 1, j + 5, k + 4, Blocks.stone);
		world.setBlock(i + 1, j + 5, k + 5, Blocks.stone);
		world.setBlock(i + 1, j + 5, k + 6, Blocks.stone);
		world.setBlock(i + 1, j + 5, k + 7, Blocks.stone);
		world.setBlock(i + 1, j + 5, k + 8, Blocks.stone);
		world.setBlock(i + 1, j + 5, k + 9, Blocks.stone);
		world.setBlock(i + 1, j + 6, k + 0, Blocks.stone);
		world.setBlock(i + 1, j + 6, k + 1, Blocks.stone);
		world.setBlock(i + 1, j + 6, k + 2, Blocks.stone);
		world.setBlock(i + 1, j + 6, k + 3, Blocks.stone);
		world.setBlock(i + 1, j + 6, k + 4, Blocks.stone);
		world.setBlock(i + 1, j + 6, k + 5, Blocks.stone);
		world.setBlock(i + 1, j + 6, k + 6, Blocks.stone);
		world.setBlock(i + 1, j + 6, k + 7, Blocks.stone);
		world.setBlock(i + 1, j + 6, k + 8, Blocks.stone);
		world.setBlock(i + 1, j + 6, k + 9, Blocks.stone);
		world.setBlock(i + 1, j + 7, k + 0, Blocks.stone);
		world.setBlock(i + 1, j + 7, k + 1, Blocks.stone);
		world.setBlock(i + 1, j + 7, k + 2, Blocks.stone);
		world.setBlock(i + 1, j + 7, k + 3, Blocks.stone);
		world.setBlock(i + 1, j + 7, k + 4, Blocks.stone);
		world.setBlock(i + 1, j + 7, k + 5, Blocks.stone);
		world.setBlock(i + 1, j + 7, k + 6, Blocks.stone);
		world.setBlock(i + 1, j + 7, k + 7, Blocks.stone);
		world.setBlock(i + 1, j + 7, k + 8, Blocks.stone);
		world.setBlock(i + 1, j + 7, k + 9, Blocks.stone);
		world.setBlock(i + 1, j + 8, k + 0, Blocks.stone);
		world.setBlock(i + 1, j + 8, k + 1, Blocks.stone);
		world.setBlock(i + 1, j + 8, k + 2, Blocks.stone);
		world.setBlock(i + 1, j + 8, k + 3, Blocks.stone);
		world.setBlock(i + 1, j + 8, k + 4, Blocks.stone);
		world.setBlock(i + 1, j + 8, k + 5, Blocks.stone);
		world.setBlock(i + 1, j + 8, k + 6, Blocks.stone);
		world.setBlock(i + 1, j + 8, k + 7, Blocks.stone);
		world.setBlock(i + 1, j + 8, k + 8, Blocks.stone);
		world.setBlock(i + 1, j + 8, k + 9, Blocks.stone);
		world.setBlock(i + 1, j + 9, k + 0, Blocks.stone);
		world.setBlock(i + 1, j + 9, k + 1, Blocks.stone);
		world.setBlock(i + 1, j + 9, k + 2, Blocks.stone);
		world.setBlock(i + 1, j + 9, k + 3, Blocks.stone);
		world.setBlock(i + 1, j + 9, k + 4, Blocks.stone);
		world.setBlock(i + 1, j + 9, k + 5, Blocks.stone);
		world.setBlock(i + 1, j + 9, k + 6, Blocks.stone);
		world.setBlock(i + 1, j + 9, k + 7, Blocks.stone);
		world.setBlock(i + 1, j + 9, k + 8, Blocks.stone);
		world.setBlock(i + 1, j + 9, k + 9, Blocks.stone);
		world.setBlock(i + 2, j + 0, k + 0, Blocks.stone);
		world.setBlock(i + 2, j + 0, k + 1, Blocks.stone);
		world.setBlock(i + 2, j + 0, k + 2, Blocks.stone);
		world.setBlock(i + 2, j + 0, k + 3, Blocks.stone);
		world.setBlock(i + 2, j + 0, k + 4, Blocks.stone);
		world.setBlock(i + 2, j + 0, k + 5, Blocks.stone);
		world.setBlock(i + 2, j + 0, k + 6, Blocks.stone);
		world.setBlock(i + 2, j + 0, k + 7, Blocks.stone);
		world.setBlock(i + 2, j + 0, k + 8, Blocks.stone);
		world.setBlock(i + 2, j + 0, k + 9, Blocks.stone);
		world.setBlock(i + 2, j + 1, k + 0, Blocks.stone);
		world.setBlock(i + 2, j + 1, k + 1, Blocks.stone);
		world.setBlock(i + 2, j + 1, k + 2, Blocks.stone);
		world.setBlock(i + 2, j + 1, k + 3, Blocks.stone);
		world.setBlock(i + 2, j + 1, k + 4, ChaosBlocks.shatteredBedrock);
		world.setBlock(i + 2, j + 1, k + 5, ChaosBlocks.shatteredBedrock);
		world.setBlock(i + 2, j + 1, k + 6, Blocks.stone);
		world.setBlock(i + 2, j + 1, k + 7, Blocks.stone);
		world.setBlock(i + 2, j + 1, k + 8, Blocks.stone);
		world.setBlock(i + 2, j + 1, k + 9, Blocks.stone);
		world.setBlock(i + 2, j + 2, k + 0, Blocks.stone);
		world.setBlock(i + 2, j + 2, k + 1, Blocks.stone);
		world.setBlock(i + 2, j + 2, k + 2, Blocks.stone);
		world.setBlock(i + 2, j + 2, k + 3, ChaosBlocks.shatteredBedrock);
		world.setBlock(i + 2, j + 2, k + 4, Blocks.air);
		world.setBlock(i + 2, j + 2, k + 5, Blocks.air);
		world.setBlock(i + 2, j + 2, k + 6, ChaosBlocks.shatteredBedrock);
		world.setBlock(i + 2, j + 2, k + 7, Blocks.stone);
		world.setBlock(i + 2, j + 2, k + 8, Blocks.stone);
		world.setBlock(i + 2, j + 2, k + 9, Blocks.stone);
		world.setBlock(i + 2, j + 3, k + 0, Blocks.stone);
		world.setBlock(i + 2, j + 3, k + 1, Blocks.stone);
		world.setBlock(i + 2, j + 3, k + 2, Blocks.stone);
		world.setBlock(i + 2, j + 3, k + 3, ChaosBlocks.shatteredBedrock);
		world.setBlock(i + 2, j + 3, k + 4, Blocks.air);
		world.setBlock(i + 2, j + 3, k + 5, Blocks.air);
		world.setBlock(i + 2, j + 3, k + 6, ChaosBlocks.shatteredBedrock);
		world.setBlock(i + 2, j + 3, k + 7, Blocks.stone);
		world.setBlock(i + 2, j + 3, k + 8, Blocks.stone);
		world.setBlock(i + 2, j + 3, k + 9, Blocks.stone);
		world.setBlock(i + 2, j + 4, k + 0, Blocks.stone);
		world.setBlock(i + 2, j + 4, k + 1, Blocks.stone);
		world.setBlock(i + 2, j + 4, k + 2, Blocks.stone);
		world.setBlock(i + 2, j + 4, k + 3, Blocks.stone);
		world.setBlock(i + 2, j + 4, k + 4, ChaosBlocks.shatteredBedrock);
		world.setBlock(i + 2, j + 4, k + 5, ChaosBlocks.shatteredBedrock);
		world.setBlock(i + 2, j + 4, k + 6, Blocks.stone);
		world.setBlock(i + 2, j + 4, k + 7, Blocks.stone);
		world.setBlock(i + 2, j + 4, k + 8, Blocks.stone);
		world.setBlock(i + 2, j + 4, k + 9, Blocks.stone);
		world.setBlock(i + 2, j + 5, k + 0, Blocks.stone);
		world.setBlock(i + 2, j + 5, k + 1, Blocks.stone);
		world.setBlock(i + 2, j + 5, k + 2, Blocks.stone);
		world.setBlock(i + 2, j + 5, k + 3, Blocks.stone);
		world.setBlock(i + 2, j + 5, k + 4, Blocks.stone);
		world.setBlock(i + 2, j + 5, k + 5, Blocks.stone);
		world.setBlock(i + 2, j + 5, k + 6, Blocks.stone);
		world.setBlock(i + 2, j + 5, k + 7, Blocks.stone);
		world.setBlock(i + 2, j + 5, k + 8, Blocks.stone);
		world.setBlock(i + 2, j + 5, k + 9, Blocks.stone);
		world.setBlock(i + 2, j + 6, k + 0, Blocks.stone);
		world.setBlock(i + 2, j + 6, k + 1, Blocks.stone);
		world.setBlock(i + 2, j + 6, k + 2, Blocks.stone);
		world.setBlock(i + 2, j + 6, k + 3, Blocks.stone);
		world.setBlock(i + 2, j + 6, k + 4, Blocks.stone);
		world.setBlock(i + 2, j + 6, k + 5, Blocks.stone);
		world.setBlock(i + 2, j + 6, k + 6, Blocks.stone);
		world.setBlock(i + 2, j + 6, k + 7, Blocks.stone);
		world.setBlock(i + 2, j + 6, k + 8, Blocks.stone);
		world.setBlock(i + 2, j + 6, k + 9, Blocks.stone);
		world.setBlock(i + 2, j + 7, k + 0, Blocks.stone);
		world.setBlock(i + 2, j + 7, k + 1, Blocks.stone);
		world.setBlock(i + 2, j + 7, k + 2, Blocks.stone);
		world.setBlock(i + 2, j + 7, k + 3, Blocks.stone);
		world.setBlock(i + 2, j + 7, k + 4, Blocks.stone);
		world.setBlock(i + 2, j + 7, k + 5, Blocks.stone);
		world.setBlock(i + 2, j + 7, k + 6, Blocks.stone);
		world.setBlock(i + 2, j + 7, k + 7, Blocks.stone);
		world.setBlock(i + 2, j + 7, k + 8, Blocks.stone);
		world.setBlock(i + 2, j + 7, k + 9, Blocks.stone);
		world.setBlock(i + 2, j + 8, k + 0, Blocks.stone);
		world.setBlock(i + 2, j + 8, k + 1, Blocks.stone);
		world.setBlock(i + 2, j + 8, k + 2, Blocks.stone);
		world.setBlock(i + 2, j + 8, k + 3, Blocks.stone);
		world.setBlock(i + 2, j + 8, k + 4, Blocks.stone);
		world.setBlock(i + 2, j + 8, k + 5, Blocks.stone);
		world.setBlock(i + 2, j + 8, k + 6, Blocks.stone);
		world.setBlock(i + 2, j + 8, k + 7, Blocks.stone);
		world.setBlock(i + 2, j + 8, k + 8, Blocks.stone);
		world.setBlock(i + 2, j + 8, k + 9, Blocks.stone);
		world.setBlock(i + 2, j + 9, k + 0, Blocks.stone);
		world.setBlock(i + 2, j + 9, k + 1, Blocks.stone);
		world.setBlock(i + 2, j + 9, k + 2, Blocks.stone);
		world.setBlock(i + 2, j + 9, k + 3, Blocks.stone);
		world.setBlock(i + 2, j + 9, k + 4, Blocks.stone);
		world.setBlock(i + 2, j + 9, k + 5, Blocks.stone);
		world.setBlock(i + 2, j + 9, k + 6, Blocks.stone);
		world.setBlock(i + 2, j + 9, k + 7, Blocks.stone);
		world.setBlock(i + 2, j + 9, k + 8, Blocks.stone);
		world.setBlock(i + 2, j + 9, k + 9, Blocks.stone);
		world.setBlock(i + 3, j + 0, k + 0, Blocks.stone);
		world.setBlock(i + 3, j + 0, k + 1, Blocks.stone);
		world.setBlock(i + 3, j + 0, k + 2, Blocks.stone);
		world.setBlock(i + 3, j + 0, k + 3, Blocks.stone);
		world.setBlock(i + 3, j + 0, k + 4, Blocks.stone);
		world.setBlock(i + 3, j + 0, k + 5, Blocks.stone);
		world.setBlock(i + 3, j + 0, k + 6, Blocks.stone);
		world.setBlock(i + 3, j + 0, k + 7, Blocks.stone);
		world.setBlock(i + 3, j + 0, k + 8, Blocks.stone);
		world.setBlock(i + 3, j + 0, k + 9, Blocks.stone);
		world.setBlock(i + 3, j + 1, k + 0, Blocks.stone);
		world.setBlock(i + 3, j + 1, k + 1, Blocks.stone);
		world.setBlock(i + 3, j + 1, k + 2, Blocks.stone);
		world.setBlock(i + 3, j + 1, k + 3, ChaosBlocks.shatteredBedrock);
		world.setBlock(i + 3, j + 1, k + 4, ChaosBlocks.voidLamp);
		world.setBlock(i + 3, j + 1, k + 5, ChaosBlocks.voidLamp);
		world.setBlock(i + 3, j + 1, k + 6, ChaosBlocks.shatteredBedrock);
		world.setBlock(i + 3, j + 1, k + 7, Blocks.stone);
		world.setBlock(i + 3, j + 1, k + 8, Blocks.stone);
		world.setBlock(i + 3, j + 1, k + 9, Blocks.stone);
		world.setBlock(i + 3, j + 2, k + 0, Blocks.stone);
		world.setBlock(i + 3, j + 2, k + 1, Blocks.stone);
		world.setBlock(i + 3, j + 2, k + 2, ChaosBlocks.shatteredBedrock);
		world.setBlock(i + 3, j + 2, k + 3, Blocks.air);
		world.setBlock(i + 3, j + 2, k + 4, Blocks.air);
		world.setBlock(i + 3, j + 2, k + 5, Blocks.air);
		world.setBlock(i + 3, j + 2, k + 6, Blocks.air);
		world.setBlock(i + 3, j + 2, k + 7, ChaosBlocks.shatteredBedrock);
		world.setBlock(i + 3, j + 2, k + 8, Blocks.stone);
		world.setBlock(i + 3, j + 2, k + 9, Blocks.stone);
		world.setBlock(i + 3, j + 3, k + 0, Blocks.stone);
		world.setBlock(i + 3, j + 3, k + 1, Blocks.stone);
		world.setBlock(i + 3, j + 3, k + 2, ChaosBlocks.shatteredBedrock);
		world.setBlock(i + 3, j + 3, k + 3, Blocks.air);
		world.setBlock(i + 3, j + 3, k + 4, Blocks.air);
		world.setBlock(i + 3, j + 3, k + 5, Blocks.air);
		world.setBlock(i + 3, j + 3, k + 6, Blocks.air);
		world.setBlock(i + 3, j + 3, k + 7, ChaosBlocks.shatteredBedrock);
		world.setBlock(i + 3, j + 3, k + 8, Blocks.stone);
		world.setBlock(i + 3, j + 3, k + 9, Blocks.stone);
		world.setBlock(i + 3, j + 4, k + 0, Blocks.stone);
		world.setBlock(i + 3, j + 4, k + 1, Blocks.stone);
		world.setBlock(i + 3, j + 4, k + 2, Blocks.stone);
		world.setBlock(i + 3, j + 4, k + 3, ChaosBlocks.shatteredBedrock);
		world.setBlock(i + 3, j + 4, k + 4, Blocks.air);
		world.setBlock(i + 3, j + 4, k + 5, Blocks.air);
		world.setBlock(i + 3, j + 4, k + 6, ChaosBlocks.shatteredBedrock);
		world.setBlock(i + 3, j + 4, k + 7, Blocks.stone);
		world.setBlock(i + 3, j + 4, k + 8, Blocks.stone);
		world.setBlock(i + 3, j + 4, k + 9, Blocks.stone);
		world.setBlock(i + 3, j + 5, k + 0, Blocks.stone);
		world.setBlock(i + 3, j + 5, k + 1, Blocks.stone);
		world.setBlock(i + 3, j + 5, k + 2, Blocks.stone);
		world.setBlock(i + 3, j + 5, k + 3, Blocks.stone);
		world.setBlock(i + 3, j + 5, k + 4, ChaosBlocks.shatteredBedrock);
		world.setBlock(i + 3, j + 5, k + 5, ChaosBlocks.shatteredBedrock);
		world.setBlock(i + 3, j + 5, k + 6, Blocks.stone);
		world.setBlock(i + 3, j + 5, k + 7, Blocks.stone);
		world.setBlock(i + 3, j + 5, k + 8, Blocks.stone);
		world.setBlock(i + 3, j + 5, k + 9, Blocks.stone);
		world.setBlock(i + 3, j + 6, k + 0, Blocks.stone);
		world.setBlock(i + 3, j + 6, k + 1, Blocks.stone);
		world.setBlock(i + 3, j + 6, k + 2, Blocks.stone);
		world.setBlock(i + 3, j + 6, k + 3, Blocks.stone);
		world.setBlock(i + 3, j + 6, k + 4, Blocks.stone);
		world.setBlock(i + 3, j + 6, k + 5, Blocks.stone);
		world.setBlock(i + 3, j + 6, k + 6, Blocks.stone);
		world.setBlock(i + 3, j + 6, k + 7, Blocks.stone);
		world.setBlock(i + 3, j + 6, k + 8, Blocks.stone);
		world.setBlock(i + 3, j + 6, k + 9, Blocks.stone);
		world.setBlock(i + 3, j + 7, k + 0, Blocks.stone);
		world.setBlock(i + 3, j + 7, k + 1, Blocks.stone);
		world.setBlock(i + 3, j + 7, k + 2, Blocks.stone);
		world.setBlock(i + 3, j + 7, k + 3, Blocks.stone);
		world.setBlock(i + 3, j + 7, k + 4, Blocks.stone);
		world.setBlock(i + 3, j + 7, k + 5, Blocks.stone);
		world.setBlock(i + 3, j + 7, k + 6, Blocks.stone);
		world.setBlock(i + 3, j + 7, k + 7, Blocks.stone);
		world.setBlock(i + 3, j + 7, k + 8, Blocks.stone);
		world.setBlock(i + 3, j + 7, k + 9, Blocks.stone);
		world.setBlock(i + 3, j + 8, k + 0, Blocks.stone);
		world.setBlock(i + 3, j + 8, k + 1, Blocks.stone);
		world.setBlock(i + 3, j + 8, k + 2, Blocks.stone);
		world.setBlock(i + 3, j + 8, k + 3, Blocks.stone);
		world.setBlock(i + 3, j + 8, k + 4, Blocks.stone);
		world.setBlock(i + 3, j + 8, k + 5, Blocks.stone);
		world.setBlock(i + 3, j + 8, k + 6, Blocks.stone);
		world.setBlock(i + 3, j + 8, k + 7, Blocks.stone);
		world.setBlock(i + 3, j + 8, k + 8, Blocks.stone);
		world.setBlock(i + 3, j + 8, k + 9, Blocks.stone);
		world.setBlock(i + 3, j + 9, k + 0, Blocks.stone);
		world.setBlock(i + 3, j + 9, k + 1, Blocks.stone);
		world.setBlock(i + 3, j + 9, k + 2, Blocks.stone);
		world.setBlock(i + 3, j + 9, k + 3, Blocks.stone);
		world.setBlock(i + 3, j + 9, k + 4, Blocks.stone);
		world.setBlock(i + 3, j + 9, k + 5, Blocks.stone);
		world.setBlock(i + 3, j + 9, k + 6, Blocks.stone);
		world.setBlock(i + 3, j + 9, k + 7, Blocks.stone);
		world.setBlock(i + 3, j + 9, k + 8, Blocks.stone);
		world.setBlock(i + 3, j + 9, k + 9, Blocks.stone);
		world.setBlock(i + 4, j + 0, k + 0, Blocks.stone);
		world.setBlock(i + 4, j + 0, k + 1, Blocks.stone);
		world.setBlock(i + 4, j + 0, k + 2, Blocks.stone);
		world.setBlock(i + 4, j + 0, k + 3, Blocks.stone);
		world.setBlock(i + 4, j + 0, k + 4, Blocks.bedrock);
		world.setBlock(i + 4, j + 0, k + 5, Blocks.lapis_block);
		world.setBlock(i + 4, j + 0, k + 6, Blocks.stone);
		world.setBlock(i + 4, j + 0, k + 7, Blocks.stone);
		world.setBlock(i + 4, j + 0, k + 8, Blocks.stone);
		world.setBlock(i + 4, j + 0, k + 9, Blocks.stone);
		world.setBlock(i + 4, j + 1, k + 0, Blocks.stone);
		world.setBlock(i + 4, j + 1, k + 1, Blocks.stone);
		world.setBlock(i + 4, j + 1, k + 2, ChaosBlocks.shatteredBedrock);
		world.setBlock(i + 4, j + 1, k + 3, ChaosBlocks.voidLamp);
		world.setBlock(i + 4, j + 1, k + 4, Blocks.air);
		world.setBlock(i + 4, j + 1, k + 5, Blocks.air);
		world.setBlock(i + 4, j + 1, k + 6, ChaosBlocks.voidLamp);
		world.setBlock(i + 4, j + 1, k + 7, ChaosBlocks.shatteredBedrock);
		world.setBlock(i + 4, j + 1, k + 8, Blocks.stone);
		world.setBlock(i + 4, j + 1, k + 9, Blocks.stone);
		world.setBlock(i + 4, j + 2, k + 0, Blocks.stone);
		world.setBlock(i + 4, j + 2, k + 2, Blocks.air);
		world.setBlock(i + 4, j + 2, k + 3, Blocks.air);
		world.setBlock(i + 4, j + 2, k + 4, Blocks.air);
		world.setBlock(i + 4, j + 2, k + 5, Blocks.air);
		world.setBlock(i + 4, j + 2, k + 6, Blocks.air);
		world.setBlock(i + 4, j + 2, k + 7, Blocks.air);
		world.setBlock(i + 4, j + 2, k + 9, Blocks.stone);
		world.setBlock(i + 4, j + 3, k + 0, Blocks.stone);
		world.setBlock(i + 4, j + 3, k + 2, Blocks.air);
		world.setBlock(i + 4, j + 3, k + 3, Blocks.air);
		world.setBlock(i + 4, j + 3, k + 4, Blocks.air);
		world.setBlock(i + 4, j + 3, k + 5, Blocks.air);
		world.setBlock(i + 4, j + 3, k + 6, Blocks.air);
		world.setBlock(i + 4, j + 3, k + 7, Blocks.air);
		world.setBlock(i + 4, j + 3, k + 9, Blocks.stone);
		world.setBlock(i + 4, j + 4, k + 0, Blocks.stone);
		world.setBlock(i + 4, j + 4, k + 1, Blocks.stone);
		world.setBlock(i + 4, j + 4, k + 2, ChaosBlocks.shatteredBedrock);
		world.setBlock(i + 4, j + 4, k + 3, Blocks.air);
		world.setBlock(i + 4, j + 4, k + 4, Blocks.air);
		world.setBlock(i + 4, j + 4, k + 5, Blocks.air);
		world.setBlock(i + 4, j + 4, k + 6, Blocks.air);
		world.setBlock(i + 4, j + 4, k + 7, ChaosBlocks.shatteredBedrock);
		world.setBlock(i + 4, j + 4, k + 8, Blocks.stone);
		world.setBlock(i + 4, j + 4, k + 9, Blocks.stone);
		world.setBlock(i + 4, j + 5, k + 0, Blocks.stone);
		world.setBlock(i + 4, j + 5, k + 1, Blocks.stone);
		world.setBlock(i + 4, j + 5, k + 2, Blocks.stone);
		world.setBlock(i + 4, j + 5, k + 3, ChaosBlocks.shatteredBedrock);
		world.setBlock(i + 4, j + 5, k + 4, Blocks.air);
		world.setBlock(i + 4, j + 5, k + 5, Blocks.air);
		world.setBlock(i + 4, j + 5, k + 6, ChaosBlocks.shatteredBedrock);
		world.setBlock(i + 4, j + 5, k + 7, Blocks.stone);
		world.setBlock(i + 4, j + 5, k + 8, Blocks.stone);
		world.setBlock(i + 4, j + 5, k + 9, Blocks.stone);
		world.setBlock(i + 4, j + 6, k + 0, Blocks.stone);
		world.setBlock(i + 4, j + 6, k + 1, Blocks.stone);
		world.setBlock(i + 4, j + 6, k + 2, Blocks.stone);
		world.setBlock(i + 4, j + 6, k + 3, Blocks.stone);
		world.setBlock(i + 4, j + 6, k + 4, ChaosBlocks.voidLamp);
		world.setBlock(i + 4, j + 6, k + 5, ChaosBlocks.voidLamp);
		world.setBlock(i + 4, j + 6, k + 6, Blocks.stone);
		world.setBlock(i + 4, j + 6, k + 7, Blocks.stone);
		world.setBlock(i + 4, j + 6, k + 8, Blocks.stone);
		world.setBlock(i + 4, j + 6, k + 9, Blocks.stone);
		world.setBlock(i + 4, j + 7, k + 0, Blocks.stone);
		world.setBlock(i + 4, j + 7, k + 1, Blocks.stone);
		world.setBlock(i + 4, j + 7, k + 2, Blocks.stone);
		world.setBlock(i + 4, j + 7, k + 3, Blocks.stone);
		world.setBlock(i + 4, j + 7, k + 4, Blocks.stone);
		world.setBlock(i + 4, j + 7, k + 5, Blocks.stone);
		world.setBlock(i + 4, j + 7, k + 6, Blocks.stone);
		world.setBlock(i + 4, j + 7, k + 7, Blocks.stone);
		world.setBlock(i + 4, j + 7, k + 8, Blocks.stone);
		world.setBlock(i + 4, j + 7, k + 9, Blocks.stone);
		world.setBlock(i + 4, j + 8, k + 0, Blocks.stone);
		world.setBlock(i + 4, j + 8, k + 1, Blocks.stone);
		world.setBlock(i + 4, j + 8, k + 2, Blocks.stone);
		world.setBlock(i + 4, j + 8, k + 3, Blocks.stone);
		world.setBlock(i + 4, j + 8, k + 4, Blocks.stone);
		world.setBlock(i + 4, j + 8, k + 5, Blocks.stone);
		world.setBlock(i + 4, j + 8, k + 6, Blocks.stone);
		world.setBlock(i + 4, j + 8, k + 7, Blocks.stone);
		world.setBlock(i + 4, j + 8, k + 8, Blocks.stone);
		world.setBlock(i + 4, j + 8, k + 9, Blocks.stone);
		world.setBlock(i + 4, j + 9, k + 0, Blocks.stone);
		world.setBlock(i + 4, j + 9, k + 1, Blocks.stone);
		world.setBlock(i + 4, j + 9, k + 2, Blocks.stone);
		world.setBlock(i + 4, j + 9, k + 3, Blocks.stone);
		world.setBlock(i + 4, j + 9, k + 4, Blocks.stone);
		world.setBlock(i + 4, j + 9, k + 5, Blocks.stone);
		world.setBlock(i + 4, j + 9, k + 6, Blocks.stone);
		world.setBlock(i + 4, j + 9, k + 7, Blocks.stone);
		world.setBlock(i + 4, j + 9, k + 8, Blocks.stone);
		world.setBlock(i + 4, j + 9, k + 9, Blocks.stone);
		world.setBlock(i + 5, j + 0, k + 0, Blocks.stone);
		world.setBlock(i + 5, j + 0, k + 1, Blocks.stone);
		world.setBlock(i + 5, j + 0, k + 2, Blocks.stone);
		world.setBlock(i + 5, j + 0, k + 3, Blocks.stone);
		world.setBlock(i + 5, j + 0, k + 4, Blocks.bedrock);
		world.setBlock(i + 5, j + 0, k + 5, Blocks.bedrock);
		world.setBlock(i + 5, j + 0, k + 6, Blocks.stone);
		world.setBlock(i + 5, j + 0, k + 7, Blocks.stone);
		world.setBlock(i + 5, j + 0, k + 8, Blocks.stone);
		world.setBlock(i + 5, j + 0, k + 9, Blocks.stone);
		world.setBlock(i + 5, j + 1, k + 0, Blocks.stone);
		world.setBlock(i + 5, j + 1, k + 1, Blocks.stone);
		world.setBlock(i + 5, j + 1, k + 2, ChaosBlocks.shatteredBedrock);
		world.setBlock(i + 5, j + 1, k + 3, ChaosBlocks.voidLamp);
		world.setBlock(i + 5, j + 1, k + 4, Blocks.air);
		world.setBlock(i + 5, j + 1, k + 5, Blocks.air);
		world.setBlock(i + 5, j + 1, k + 6, ChaosBlocks.voidLamp);
		world.setBlock(i + 5, j + 1, k + 7, ChaosBlocks.shatteredBedrock);
		world.setBlock(i + 5, j + 1, k + 8, Blocks.stone);
		world.setBlock(i + 5, j + 1, k + 9, Blocks.stone);
		world.setBlock(i + 5, j + 2, k + 0, Blocks.stone);
		world.setBlock(i + 5, j + 2, k + 2, Blocks.air);
		world.setBlock(i + 5, j + 2, k + 3, Blocks.air);
		world.setBlock(i + 5, j + 2, k + 4, Blocks.air);
		world.setBlock(i + 5, j + 2, k + 5, Blocks.air);
		world.setBlock(i + 5, j + 2, k + 6, Blocks.air);
		world.setBlock(i + 5, j + 2, k + 7, Blocks.air);
		world.setBlock(i + 5, j + 2, k + 9, Blocks.stone);
		world.setBlock(i + 5, j + 3, k + 0, Blocks.stone);
		world.setBlock(i + 5, j + 3, k + 2, Blocks.air);
		world.setBlock(i + 5, j + 3, k + 3, Blocks.air);
		world.setBlock(i + 5, j + 3, k + 4, Blocks.air);
		world.setBlock(i + 5, j + 3, k + 5, Blocks.air);
		world.setBlock(i + 5, j + 3, k + 6, Blocks.air);
		world.setBlock(i + 5, j + 3, k + 7, Blocks.air);
		world.setBlock(i + 5, j + 3, k + 9, Blocks.stone);
		world.setBlock(i + 5, j + 4, k + 0, Blocks.stone);
		world.setBlock(i + 5, j + 4, k + 1, Blocks.stone);
		world.setBlock(i + 5, j + 4, k + 2, ChaosBlocks.shatteredBedrock);
		world.setBlock(i + 5, j + 4, k + 3, Blocks.air);
		world.setBlock(i + 5, j + 4, k + 4, Blocks.air);
		world.setBlock(i + 5, j + 4, k + 5, Blocks.air);
		world.setBlock(i + 5, j + 4, k + 6, Blocks.air);
		world.setBlock(i + 5, j + 4, k + 7, ChaosBlocks.shatteredBedrock);
		world.setBlock(i + 5, j + 4, k + 8, Blocks.stone);
		world.setBlock(i + 5, j + 4, k + 9, Blocks.stone);
		world.setBlock(i + 5, j + 5, k + 0, Blocks.stone);
		world.setBlock(i + 5, j + 5, k + 1, Blocks.stone);
		world.setBlock(i + 5, j + 5, k + 2, Blocks.stone);
		world.setBlock(i + 5, j + 5, k + 3, ChaosBlocks.shatteredBedrock);
		world.setBlock(i + 5, j + 5, k + 4, Blocks.air);
		world.setBlock(i + 5, j + 5, k + 5, Blocks.air);
		world.setBlock(i + 5, j + 5, k + 6, ChaosBlocks.shatteredBedrock);
		world.setBlock(i + 5, j + 5, k + 7, Blocks.stone);
		world.setBlock(i + 5, j + 5, k + 8, Blocks.stone);
		world.setBlock(i + 5, j + 5, k + 9, Blocks.stone);
		world.setBlock(i + 5, j + 6, k + 0, Blocks.stone);
		world.setBlock(i + 5, j + 6, k + 1, Blocks.stone);
		world.setBlock(i + 5, j + 6, k + 2, Blocks.stone);
		world.setBlock(i + 5, j + 6, k + 3, Blocks.stone);
		world.setBlock(i + 5, j + 6, k + 4, ChaosBlocks.voidLamp);
		world.setBlock(i + 5, j + 6, k + 5, ChaosBlocks.voidLamp);
		world.setBlock(i + 5, j + 6, k + 6, Blocks.stone);
		world.setBlock(i + 5, j + 6, k + 7, Blocks.stone);
		world.setBlock(i + 5, j + 6, k + 8, Blocks.stone);
		world.setBlock(i + 5, j + 6, k + 9, Blocks.stone);
		world.setBlock(i + 5, j + 7, k + 0, Blocks.stone);
		world.setBlock(i + 5, j + 7, k + 1, Blocks.stone);
		world.setBlock(i + 5, j + 7, k + 2, Blocks.stone);
		world.setBlock(i + 5, j + 7, k + 3, Blocks.stone);
		world.setBlock(i + 5, j + 7, k + 4, Blocks.stone);
		world.setBlock(i + 5, j + 7, k + 5, Blocks.stone);
		world.setBlock(i + 5, j + 7, k + 6, Blocks.stone);
		world.setBlock(i + 5, j + 7, k + 7, Blocks.stone);
		world.setBlock(i + 5, j + 7, k + 8, Blocks.stone);
		world.setBlock(i + 5, j + 7, k + 9, Blocks.stone);
		world.setBlock(i + 5, j + 8, k + 0, Blocks.stone);
		world.setBlock(i + 5, j + 8, k + 1, Blocks.stone);
		world.setBlock(i + 5, j + 8, k + 2, Blocks.stone);
		world.setBlock(i + 5, j + 8, k + 3, Blocks.stone);
		world.setBlock(i + 5, j + 8, k + 4, Blocks.stone);
		world.setBlock(i + 5, j + 8, k + 5, Blocks.stone);
		world.setBlock(i + 5, j + 8, k + 6, Blocks.stone);
		world.setBlock(i + 5, j + 8, k + 7, Blocks.stone);
		world.setBlock(i + 5, j + 8, k + 8, Blocks.stone);
		world.setBlock(i + 5, j + 8, k + 9, Blocks.stone);
		world.setBlock(i + 5, j + 9, k + 0, Blocks.stone);
		world.setBlock(i + 5, j + 9, k + 1, Blocks.stone);
		world.setBlock(i + 5, j + 9, k + 2, Blocks.stone);
		world.setBlock(i + 5, j + 9, k + 3, Blocks.stone);
		world.setBlock(i + 5, j + 9, k + 4, Blocks.stone);
		world.setBlock(i + 5, j + 9, k + 5, Blocks.stone);
		world.setBlock(i + 5, j + 9, k + 6, Blocks.stone);
		world.setBlock(i + 5, j + 9, k + 7, Blocks.stone);
		world.setBlock(i + 5, j + 9, k + 8, Blocks.stone);
		world.setBlock(i + 5, j + 9, k + 9, Blocks.stone);
		world.setBlock(i + 6, j + 0, k + 0, Blocks.stone);
		world.setBlock(i + 6, j + 0, k + 1, Blocks.stone);
		world.setBlock(i + 6, j + 0, k + 2, Blocks.stone);
		world.setBlock(i + 6, j + 0, k + 3, Blocks.stone);
		world.setBlock(i + 6, j + 0, k + 4, Blocks.stone);
		world.setBlock(i + 6, j + 0, k + 5, Blocks.stone);
		world.setBlock(i + 6, j + 0, k + 6, Blocks.stone);
		world.setBlock(i + 6, j + 0, k + 7, Blocks.stone);
		world.setBlock(i + 6, j + 0, k + 8, Blocks.stone);
		world.setBlock(i + 6, j + 0, k + 9, Blocks.stone);
		world.setBlock(i + 6, j + 1, k + 0, Blocks.stone);
		world.setBlock(i + 6, j + 1, k + 1, Blocks.stone);
		world.setBlock(i + 6, j + 1, k + 2, Blocks.stone);
		world.setBlock(i + 6, j + 1, k + 3, ChaosBlocks.shatteredBedrock);
		world.setBlock(i + 6, j + 1, k + 4, ChaosBlocks.voidLamp);
		world.setBlock(i + 6, j + 1, k + 5, ChaosBlocks.voidLamp);
		world.setBlock(i + 6, j + 1, k + 6, ChaosBlocks.shatteredBedrock);
		world.setBlock(i + 6, j + 1, k + 7, Blocks.stone);
		world.setBlock(i + 6, j + 1, k + 8, Blocks.stone);
		world.setBlock(i + 6, j + 1, k + 9, Blocks.stone);
		world.setBlock(i + 6, j + 2, k + 0, Blocks.stone);
		world.setBlock(i + 6, j + 2, k + 1, Blocks.stone);
		world.setBlock(i + 6, j + 2, k + 2, ChaosBlocks.shatteredBedrock);
		world.setBlock(i + 6, j + 2, k + 3, Blocks.air);
		world.setBlock(i + 6, j + 2, k + 4, Blocks.air);
		world.setBlock(i + 6, j + 2, k + 5, Blocks.air);
		world.setBlock(i + 6, j + 2, k + 6, Blocks.air);
		world.setBlock(i + 6, j + 2, k + 7, ChaosBlocks.shatteredBedrock);
		world.setBlock(i + 6, j + 2, k + 8, Blocks.stone);
		world.setBlock(i + 6, j + 2, k + 9, Blocks.stone);
		world.setBlock(i + 6, j + 3, k + 0, Blocks.stone);
		world.setBlock(i + 6, j + 3, k + 1, Blocks.stone);
		world.setBlock(i + 6, j + 3, k + 2, ChaosBlocks.shatteredBedrock);
		world.setBlock(i + 6, j + 3, k + 3, Blocks.air);
		world.setBlock(i + 6, j + 3, k + 4, Blocks.air);
		world.setBlock(i + 6, j + 3, k + 5, Blocks.air);
		world.setBlock(i + 6, j + 3, k + 6, Blocks.air);
		world.setBlock(i + 6, j + 3, k + 7, ChaosBlocks.shatteredBedrock);
		world.setBlock(i + 6, j + 3, k + 8, Blocks.stone);
		world.setBlock(i + 6, j + 3, k + 9, Blocks.stone);
		world.setBlock(i + 6, j + 4, k + 0, Blocks.stone);
		world.setBlock(i + 6, j + 4, k + 1, Blocks.stone);
		world.setBlock(i + 6, j + 4, k + 2, Blocks.stone);
		world.setBlock(i + 6, j + 4, k + 3, ChaosBlocks.shatteredBedrock);
		world.setBlock(i + 6, j + 4, k + 4, Blocks.air);
		world.setBlock(i + 6, j + 4, k + 5, Blocks.air);
		world.setBlock(i + 6, j + 4, k + 6, ChaosBlocks.shatteredBedrock);
		world.setBlock(i + 6, j + 4, k + 7, Blocks.stone);
		world.setBlock(i + 6, j + 4, k + 8, Blocks.stone);
		world.setBlock(i + 6, j + 4, k + 9, Blocks.stone);
		world.setBlock(i + 6, j + 5, k + 0, Blocks.stone);
		world.setBlock(i + 6, j + 5, k + 1, Blocks.stone);
		world.setBlock(i + 6, j + 5, k + 2, Blocks.stone);
		world.setBlock(i + 6, j + 5, k + 3, Blocks.stone);
		world.setBlock(i + 6, j + 5, k + 4, ChaosBlocks.shatteredBedrock);
		world.setBlock(i + 6, j + 5, k + 5, ChaosBlocks.shatteredBedrock);
		world.setBlock(i + 6, j + 5, k + 6, Blocks.stone);
		world.setBlock(i + 6, j + 5, k + 7, Blocks.stone);
		world.setBlock(i + 6, j + 5, k + 8, Blocks.stone);
		world.setBlock(i + 6, j + 5, k + 9, Blocks.stone);
		world.setBlock(i + 6, j + 6, k + 0, Blocks.stone);
		world.setBlock(i + 6, j + 6, k + 1, Blocks.stone);
		world.setBlock(i + 6, j + 6, k + 2, Blocks.stone);
		world.setBlock(i + 6, j + 6, k + 3, Blocks.stone);
		world.setBlock(i + 6, j + 6, k + 4, Blocks.stone);
		world.setBlock(i + 6, j + 6, k + 5, Blocks.stone);
		world.setBlock(i + 6, j + 6, k + 6, Blocks.stone);
		world.setBlock(i + 6, j + 6, k + 7, Blocks.stone);
		world.setBlock(i + 6, j + 6, k + 8, Blocks.stone);
		world.setBlock(i + 6, j + 6, k + 9, Blocks.stone);
		world.setBlock(i + 6, j + 7, k + 0, Blocks.stone);
		world.setBlock(i + 6, j + 7, k + 1, Blocks.stone);
		world.setBlock(i + 6, j + 7, k + 2, Blocks.stone);
		world.setBlock(i + 6, j + 7, k + 3, Blocks.stone);
		world.setBlock(i + 6, j + 7, k + 4, Blocks.stone);
		world.setBlock(i + 6, j + 7, k + 5, Blocks.stone);
		world.setBlock(i + 6, j + 7, k + 6, Blocks.stone);
		world.setBlock(i + 6, j + 7, k + 7, Blocks.stone);
		world.setBlock(i + 6, j + 7, k + 8, Blocks.stone);
		world.setBlock(i + 6, j + 7, k + 9, Blocks.stone);
		world.setBlock(i + 6, j + 8, k + 0, Blocks.stone);
		world.setBlock(i + 6, j + 8, k + 1, Blocks.stone);
		world.setBlock(i + 6, j + 8, k + 2, Blocks.stone);
		world.setBlock(i + 6, j + 8, k + 3, Blocks.stone);
		world.setBlock(i + 6, j + 8, k + 4, Blocks.stone);
		world.setBlock(i + 6, j + 8, k + 5, Blocks.stone);
		world.setBlock(i + 6, j + 8, k + 6, Blocks.stone);
		world.setBlock(i + 6, j + 8, k + 7, Blocks.stone);
		world.setBlock(i + 6, j + 8, k + 8, Blocks.stone);
		world.setBlock(i + 6, j + 8, k + 9, Blocks.stone);
		world.setBlock(i + 6, j + 9, k + 0, Blocks.stone);
		world.setBlock(i + 6, j + 9, k + 1, Blocks.stone);
		world.setBlock(i + 6, j + 9, k + 2, Blocks.stone);
		world.setBlock(i + 6, j + 9, k + 3, Blocks.stone);
		world.setBlock(i + 6, j + 9, k + 4, Blocks.stone);
		world.setBlock(i + 6, j + 9, k + 5, Blocks.stone);
		world.setBlock(i + 6, j + 9, k + 6, Blocks.stone);
		world.setBlock(i + 6, j + 9, k + 7, Blocks.stone);
		world.setBlock(i + 6, j + 9, k + 8, Blocks.stone);
		world.setBlock(i + 6, j + 9, k + 9, Blocks.stone);
		world.setBlock(i + 7, j + 0, k + 0, Blocks.stone);
		world.setBlock(i + 7, j + 0, k + 1, Blocks.stone);
		world.setBlock(i + 7, j + 0, k + 2, Blocks.stone);
		world.setBlock(i + 7, j + 0, k + 3, Blocks.stone);
		world.setBlock(i + 7, j + 0, k + 4, Blocks.stone);
		world.setBlock(i + 7, j + 0, k + 5, Blocks.stone);
		world.setBlock(i + 7, j + 0, k + 6, Blocks.stone);
		world.setBlock(i + 7, j + 0, k + 7, Blocks.stone);
		world.setBlock(i + 7, j + 0, k + 8, Blocks.stone);
		world.setBlock(i + 7, j + 0, k + 9, Blocks.stone);
		world.setBlock(i + 7, j + 1, k + 0, Blocks.stone);
		world.setBlock(i + 7, j + 1, k + 1, Blocks.stone);
		world.setBlock(i + 7, j + 1, k + 2, Blocks.stone);
		world.setBlock(i + 7, j + 1, k + 3, Blocks.stone);
		world.setBlock(i + 7, j + 1, k + 4, ChaosBlocks.shatteredBedrock);
		world.setBlock(i + 7, j + 1, k + 5, ChaosBlocks.shatteredBedrock);
		world.setBlock(i + 7, j + 1, k + 6, Blocks.stone);
		world.setBlock(i + 7, j + 1, k + 7, Blocks.stone);
		world.setBlock(i + 7, j + 1, k + 8, Blocks.stone);
		world.setBlock(i + 7, j + 1, k + 9, Blocks.stone);
		world.setBlock(i + 7, j + 2, k + 0, Blocks.stone);
		world.setBlock(i + 7, j + 2, k + 1, Blocks.stone);
		world.setBlock(i + 7, j + 2, k + 2, Blocks.stone);
		world.setBlock(i + 7, j + 2, k + 3, ChaosBlocks.shatteredBedrock);
		world.setBlock(i + 7, j + 2, k + 4, Blocks.air);
		world.setBlock(i + 7, j + 2, k + 5, Blocks.air);
		world.setBlock(i + 7, j + 2, k + 6, ChaosBlocks.shatteredBedrock);
		world.setBlock(i + 7, j + 2, k + 7, Blocks.stone);
		world.setBlock(i + 7, j + 2, k + 8, Blocks.stone);
		world.setBlock(i + 7, j + 2, k + 9, Blocks.stone);
		world.setBlock(i + 7, j + 3, k + 0, Blocks.stone);
		world.setBlock(i + 7, j + 3, k + 1, Blocks.stone);
		world.setBlock(i + 7, j + 3, k + 2, Blocks.stone);
		world.setBlock(i + 7, j + 3, k + 3, ChaosBlocks.shatteredBedrock);
		world.setBlock(i + 7, j + 3, k + 4, Blocks.air);
		world.setBlock(i + 7, j + 3, k + 5, Blocks.air);
		world.setBlock(i + 7, j + 3, k + 6, ChaosBlocks.shatteredBedrock);
		world.setBlock(i + 7, j + 3, k + 7, Blocks.stone);
		world.setBlock(i + 7, j + 3, k + 8, Blocks.stone);
		world.setBlock(i + 7, j + 3, k + 9, Blocks.stone);
		world.setBlock(i + 7, j + 4, k + 0, Blocks.stone);
		world.setBlock(i + 7, j + 4, k + 1, Blocks.stone);
		world.setBlock(i + 7, j + 4, k + 2, Blocks.stone);
		world.setBlock(i + 7, j + 4, k + 3, Blocks.stone);
		world.setBlock(i + 7, j + 4, k + 4, ChaosBlocks.shatteredBedrock);
		world.setBlock(i + 7, j + 4, k + 5, ChaosBlocks.shatteredBedrock);
		world.setBlock(i + 7, j + 4, k + 6, Blocks.stone);
		world.setBlock(i + 7, j + 4, k + 7, Blocks.stone);
		world.setBlock(i + 7, j + 4, k + 8, Blocks.stone);
		world.setBlock(i + 7, j + 4, k + 9, Blocks.stone);
		world.setBlock(i + 7, j + 5, k + 0, Blocks.stone);
		world.setBlock(i + 7, j + 5, k + 1, Blocks.stone);
		world.setBlock(i + 7, j + 5, k + 2, Blocks.stone);
		world.setBlock(i + 7, j + 5, k + 3, Blocks.stone);
		world.setBlock(i + 7, j + 5, k + 4, Blocks.stone);
		world.setBlock(i + 7, j + 5, k + 5, Blocks.stone);
		world.setBlock(i + 7, j + 5, k + 6, Blocks.stone);
		world.setBlock(i + 7, j + 5, k + 7, Blocks.stone);
		world.setBlock(i + 7, j + 5, k + 8, Blocks.stone);
		world.setBlock(i + 7, j + 5, k + 9, Blocks.stone);
		world.setBlock(i + 7, j + 6, k + 0, Blocks.stone);
		world.setBlock(i + 7, j + 6, k + 1, Blocks.stone);
		world.setBlock(i + 7, j + 6, k + 2, Blocks.stone);
		world.setBlock(i + 7, j + 6, k + 3, Blocks.stone);
		world.setBlock(i + 7, j + 6, k + 4, Blocks.stone);
		world.setBlock(i + 7, j + 6, k + 5, Blocks.stone);
		world.setBlock(i + 7, j + 6, k + 6, Blocks.stone);
		world.setBlock(i + 7, j + 6, k + 7, Blocks.stone);
		world.setBlock(i + 7, j + 6, k + 8, Blocks.stone);
		world.setBlock(i + 7, j + 6, k + 9, Blocks.stone);
		world.setBlock(i + 7, j + 7, k + 0, Blocks.stone);
		world.setBlock(i + 7, j + 7, k + 1, Blocks.stone);
		world.setBlock(i + 7, j + 7, k + 2, Blocks.stone);
		world.setBlock(i + 7, j + 7, k + 3, Blocks.stone);
		world.setBlock(i + 7, j + 7, k + 4, Blocks.stone);
		world.setBlock(i + 7, j + 7, k + 5, Blocks.stone);
		world.setBlock(i + 7, j + 7, k + 6, Blocks.stone);
		world.setBlock(i + 7, j + 7, k + 7, Blocks.stone);
		world.setBlock(i + 7, j + 7, k + 8, Blocks.stone);
		world.setBlock(i + 7, j + 7, k + 9, Blocks.stone);
		world.setBlock(i + 7, j + 8, k + 0, Blocks.stone);
		world.setBlock(i + 7, j + 8, k + 1, Blocks.stone);
		world.setBlock(i + 7, j + 8, k + 2, Blocks.stone);
		world.setBlock(i + 7, j + 8, k + 3, Blocks.stone);
		world.setBlock(i + 7, j + 8, k + 4, Blocks.stone);
		world.setBlock(i + 7, j + 8, k + 5, Blocks.stone);
		world.setBlock(i + 7, j + 8, k + 6, Blocks.stone);
		world.setBlock(i + 7, j + 8, k + 7, Blocks.stone);
		world.setBlock(i + 7, j + 8, k + 8, Blocks.stone);
		world.setBlock(i + 7, j + 8, k + 9, Blocks.stone);
		world.setBlock(i + 7, j + 9, k + 0, Blocks.stone);
		world.setBlock(i + 7, j + 9, k + 1, Blocks.stone);
		world.setBlock(i + 7, j + 9, k + 2, Blocks.stone);
		world.setBlock(i + 7, j + 9, k + 3, Blocks.stone);
		world.setBlock(i + 7, j + 9, k + 4, Blocks.stone);
		world.setBlock(i + 7, j + 9, k + 5, Blocks.stone);
		world.setBlock(i + 7, j + 9, k + 6, Blocks.stone);
		world.setBlock(i + 7, j + 9, k + 7, Blocks.stone);
		world.setBlock(i + 7, j + 9, k + 8, Blocks.stone);
		world.setBlock(i + 7, j + 9, k + 9, Blocks.stone);
		world.setBlock(i + 8, j + 0, k + 0, Blocks.stone);
		world.setBlock(i + 8, j + 0, k + 1, Blocks.stone);
		world.setBlock(i + 8, j + 0, k + 2, Blocks.stone);
		world.setBlock(i + 8, j + 0, k + 3, Blocks.stone);
		world.setBlock(i + 8, j + 0, k + 4, Blocks.stone);
		world.setBlock(i + 8, j + 0, k + 5, Blocks.stone);
		world.setBlock(i + 8, j + 0, k + 6, Blocks.stone);
		world.setBlock(i + 8, j + 0, k + 7, Blocks.stone);
		world.setBlock(i + 8, j + 0, k + 8, Blocks.stone);
		world.setBlock(i + 8, j + 0, k + 9, Blocks.stone);
		world.setBlock(i + 8, j + 1, k + 0, Blocks.stone);
		world.setBlock(i + 8, j + 1, k + 1, Blocks.stone);
		world.setBlock(i + 8, j + 1, k + 2, Blocks.stone);
		world.setBlock(i + 8, j + 1, k + 3, Blocks.stone);
		world.setBlock(i + 8, j + 1, k + 4, Blocks.stone);
		world.setBlock(i + 8, j + 1, k + 5, Blocks.stone);
		world.setBlock(i + 8, j + 1, k + 6, Blocks.stone);
		world.setBlock(i + 8, j + 1, k + 7, Blocks.stone);
		world.setBlock(i + 8, j + 1, k + 8, Blocks.stone);
		world.setBlock(i + 8, j + 1, k + 9, Blocks.stone);
		world.setBlock(i + 8, j + 2, k + 0, Blocks.stone);
		world.setBlock(i + 8, j + 2, k + 1, Blocks.stone);
		world.setBlock(i + 8, j + 2, k + 2, Blocks.stone);
		world.setBlock(i + 8, j + 2, k + 3, Blocks.stone);
		world.setBlock(i + 8, j + 2, k + 6, Blocks.stone);
		world.setBlock(i + 8, j + 2, k + 7, Blocks.stone);
		world.setBlock(i + 8, j + 2, k + 8, Blocks.stone);
		world.setBlock(i + 8, j + 2, k + 9, Blocks.stone);
		world.setBlock(i + 8, j + 3, k + 0, Blocks.stone);
		world.setBlock(i + 8, j + 3, k + 1, Blocks.stone);
		world.setBlock(i + 8, j + 3, k + 2, Blocks.stone);
		world.setBlock(i + 8, j + 3, k + 3, Blocks.stone);
		world.setBlock(i + 8, j + 3, k + 6, Blocks.stone);
		world.setBlock(i + 8, j + 3, k + 7, Blocks.stone);
		world.setBlock(i + 8, j + 3, k + 8, Blocks.stone);
		world.setBlock(i + 8, j + 3, k + 9, Blocks.stone);
		world.setBlock(i + 8, j + 4, k + 0, Blocks.stone);
		world.setBlock(i + 8, j + 4, k + 1, Blocks.stone);
		world.setBlock(i + 8, j + 4, k + 2, Blocks.stone);
		world.setBlock(i + 8, j + 4, k + 3, Blocks.stone);
		world.setBlock(i + 8, j + 4, k + 4, Blocks.stone);
		world.setBlock(i + 8, j + 4, k + 5, Blocks.stone);
		world.setBlock(i + 8, j + 4, k + 6, Blocks.stone);
		world.setBlock(i + 8, j + 4, k + 7, Blocks.stone);
		world.setBlock(i + 8, j + 4, k + 8, Blocks.stone);
		world.setBlock(i + 8, j + 4, k + 9, Blocks.stone);
		world.setBlock(i + 8, j + 5, k + 0, Blocks.stone);
		world.setBlock(i + 8, j + 5, k + 1, Blocks.stone);
		world.setBlock(i + 8, j + 5, k + 2, Blocks.stone);
		world.setBlock(i + 8, j + 5, k + 3, Blocks.stone);
		world.setBlock(i + 8, j + 5, k + 4, Blocks.stone);
		world.setBlock(i + 8, j + 5, k + 5, Blocks.stone);
		world.setBlock(i + 8, j + 5, k + 6, Blocks.stone);
		world.setBlock(i + 8, j + 5, k + 7, Blocks.stone);
		world.setBlock(i + 8, j + 5, k + 8, Blocks.stone);
		world.setBlock(i + 8, j + 5, k + 9, Blocks.stone);
		world.setBlock(i + 8, j + 6, k + 0, Blocks.stone);
		world.setBlock(i + 8, j + 6, k + 1, Blocks.stone);
		world.setBlock(i + 8, j + 6, k + 2, Blocks.stone);
		world.setBlock(i + 8, j + 6, k + 3, Blocks.stone);
		world.setBlock(i + 8, j + 6, k + 4, Blocks.stone);
		world.setBlock(i + 8, j + 6, k + 5, Blocks.stone);
		world.setBlock(i + 8, j + 6, k + 6, Blocks.stone);
		world.setBlock(i + 8, j + 6, k + 7, Blocks.stone);
		world.setBlock(i + 8, j + 6, k + 8, Blocks.stone);
		world.setBlock(i + 8, j + 6, k + 9, Blocks.stone);
		world.setBlock(i + 8, j + 7, k + 0, Blocks.stone);
		world.setBlock(i + 8, j + 7, k + 1, Blocks.stone);
		world.setBlock(i + 8, j + 7, k + 2, Blocks.stone);
		world.setBlock(i + 8, j + 7, k + 3, Blocks.stone);
		world.setBlock(i + 8, j + 7, k + 4, Blocks.stone);
		world.setBlock(i + 8, j + 7, k + 5, Blocks.stone);
		world.setBlock(i + 8, j + 7, k + 6, Blocks.stone);
		world.setBlock(i + 8, j + 7, k + 7, Blocks.stone);
		world.setBlock(i + 8, j + 7, k + 8, Blocks.stone);
		world.setBlock(i + 8, j + 7, k + 9, Blocks.stone);
		world.setBlock(i + 8, j + 8, k + 0, Blocks.stone);
		world.setBlock(i + 8, j + 8, k + 1, Blocks.stone);
		world.setBlock(i + 8, j + 8, k + 2, Blocks.stone);
		world.setBlock(i + 8, j + 8, k + 3, Blocks.stone);
		world.setBlock(i + 8, j + 8, k + 4, Blocks.stone);
		world.setBlock(i + 8, j + 8, k + 5, Blocks.stone);
		world.setBlock(i + 8, j + 8, k + 6, Blocks.stone);
		world.setBlock(i + 8, j + 8, k + 7, Blocks.stone);
		world.setBlock(i + 8, j + 8, k + 8, Blocks.stone);
		world.setBlock(i + 8, j + 8, k + 9, Blocks.stone);
		world.setBlock(i + 8, j + 9, k + 0, Blocks.stone);
		world.setBlock(i + 8, j + 9, k + 1, Blocks.stone);
		world.setBlock(i + 8, j + 9, k + 2, Blocks.stone);
		world.setBlock(i + 8, j + 9, k + 3, Blocks.stone);
		world.setBlock(i + 8, j + 9, k + 4, Blocks.stone);
		world.setBlock(i + 8, j + 9, k + 5, Blocks.stone);
		world.setBlock(i + 8, j + 9, k + 6, Blocks.stone);
		world.setBlock(i + 8, j + 9, k + 7, Blocks.stone);
		world.setBlock(i + 8, j + 9, k + 8, Blocks.stone);
		world.setBlock(i + 8, j + 9, k + 9, Blocks.stone);
		world.setBlock(i + 9, j + 0, k + 0, Blocks.stone);
		world.setBlock(i + 9, j + 0, k + 1, Blocks.stone);
		world.setBlock(i + 9, j + 0, k + 2, Blocks.stone);
		world.setBlock(i + 9, j + 0, k + 3, Blocks.stone);
		world.setBlock(i + 9, j + 0, k + 4, Blocks.stone);
		world.setBlock(i + 9, j + 0, k + 5, Blocks.stone);
		world.setBlock(i + 9, j + 0, k + 6, Blocks.stone);
		world.setBlock(i + 9, j + 0, k + 7, Blocks.stone);
		world.setBlock(i + 9, j + 0, k + 8, Blocks.stone);
		world.setBlock(i + 9, j + 0, k + 9, Blocks.stone);
		world.setBlock(i + 9, j + 1, k + 0, Blocks.stone);
		world.setBlock(i + 9, j + 1, k + 1, Blocks.stone);
		world.setBlock(i + 9, j + 1, k + 2, Blocks.stone);
		world.setBlock(i + 9, j + 1, k + 3, Blocks.stone);
		world.setBlock(i + 9, j + 1, k + 4, Blocks.stone);
		world.setBlock(i + 9, j + 1, k + 5, Blocks.stone);
		world.setBlock(i + 9, j + 1, k + 6, Blocks.stone);
		world.setBlock(i + 9, j + 1, k + 7, Blocks.stone);
		world.setBlock(i + 9, j + 1, k + 8, Blocks.stone);
		world.setBlock(i + 9, j + 1, k + 9, Blocks.stone);
		world.setBlock(i + 9, j + 2, k + 0, Blocks.stone);
		world.setBlock(i + 9, j + 2, k + 1, Blocks.stone);
		world.setBlock(i + 9, j + 2, k + 2, Blocks.stone);
		world.setBlock(i + 9, j + 2, k + 3, Blocks.stone);
		world.setBlock(i + 9, j + 2, k + 4, Blocks.stone);
		world.setBlock(i + 9, j + 2, k + 5, Blocks.stone);
		world.setBlock(i + 9, j + 2, k + 6, Blocks.stone);
		world.setBlock(i + 9, j + 2, k + 7, Blocks.stone);
		world.setBlock(i + 9, j + 2, k + 8, Blocks.stone);
		world.setBlock(i + 9, j + 2, k + 9, Blocks.stone);
		world.setBlock(i + 9, j + 3, k + 0, Blocks.stone);
		world.setBlock(i + 9, j + 3, k + 1, Blocks.stone);
		world.setBlock(i + 9, j + 3, k + 2, Blocks.stone);
		world.setBlock(i + 9, j + 3, k + 3, Blocks.stone);
		world.setBlock(i + 9, j + 3, k + 4, Blocks.stone);
		world.setBlock(i + 9, j + 3, k + 5, Blocks.stone);
		world.setBlock(i + 9, j + 3, k + 6, Blocks.stone);
		world.setBlock(i + 9, j + 3, k + 7, Blocks.stone);
		world.setBlock(i + 9, j + 3, k + 8, Blocks.stone);
		world.setBlock(i + 9, j + 3, k + 9, Blocks.stone);
		world.setBlock(i + 9, j + 4, k + 0, Blocks.stone);
		world.setBlock(i + 9, j + 4, k + 1, Blocks.stone);
		world.setBlock(i + 9, j + 4, k + 2, Blocks.stone);
		world.setBlock(i + 9, j + 4, k + 3, Blocks.stone);
		world.setBlock(i + 9, j + 4, k + 4, Blocks.stone);
		world.setBlock(i + 9, j + 4, k + 5, Blocks.stone);
		world.setBlock(i + 9, j + 4, k + 6, Blocks.stone);
		world.setBlock(i + 9, j + 4, k + 7, Blocks.stone);
		world.setBlock(i + 9, j + 4, k + 8, Blocks.stone);
		world.setBlock(i + 9, j + 4, k + 9, Blocks.stone);
		world.setBlock(i + 9, j + 5, k + 0, Blocks.stone);
		world.setBlock(i + 9, j + 5, k + 1, Blocks.stone);
		world.setBlock(i + 9, j + 5, k + 2, Blocks.stone);
		world.setBlock(i + 9, j + 5, k + 3, Blocks.stone);
		world.setBlock(i + 9, j + 5, k + 4, Blocks.stone);
		world.setBlock(i + 9, j + 5, k + 5, Blocks.stone);
		world.setBlock(i + 9, j + 5, k + 6, Blocks.stone);
		world.setBlock(i + 9, j + 5, k + 7, Blocks.stone);
		world.setBlock(i + 9, j + 5, k + 8, Blocks.stone);
		world.setBlock(i + 9, j + 5, k + 9, Blocks.stone);
		world.setBlock(i + 9, j + 6, k + 0, Blocks.stone);
		world.setBlock(i + 9, j + 6, k + 1, Blocks.stone);
		world.setBlock(i + 9, j + 6, k + 2, Blocks.stone);
		world.setBlock(i + 9, j + 6, k + 3, Blocks.stone);
		world.setBlock(i + 9, j + 6, k + 4, Blocks.stone);
		world.setBlock(i + 9, j + 6, k + 5, Blocks.stone);
		world.setBlock(i + 9, j + 6, k + 6, Blocks.stone);
		world.setBlock(i + 9, j + 6, k + 7, Blocks.stone);
		world.setBlock(i + 9, j + 6, k + 8, Blocks.stone);
		world.setBlock(i + 9, j + 6, k + 9, Blocks.stone);
		world.setBlock(i + 9, j + 7, k + 0, Blocks.stone);
		world.setBlock(i + 9, j + 7, k + 1, Blocks.stone);
		world.setBlock(i + 9, j + 7, k + 2, Blocks.stone);
		world.setBlock(i + 9, j + 7, k + 3, Blocks.stone);
		world.setBlock(i + 9, j + 7, k + 4, Blocks.stone);
		world.setBlock(i + 9, j + 7, k + 5, Blocks.stone);
		world.setBlock(i + 9, j + 7, k + 6, Blocks.stone);
		world.setBlock(i + 9, j + 7, k + 7, Blocks.stone);
		world.setBlock(i + 9, j + 7, k + 8, Blocks.stone);
		world.setBlock(i + 9, j + 7, k + 9, Blocks.stone);
		world.setBlock(i + 9, j + 8, k + 0, Blocks.stone);
		world.setBlock(i + 9, j + 8, k + 1, Blocks.stone);
		world.setBlock(i + 9, j + 8, k + 2, Blocks.stone);
		world.setBlock(i + 9, j + 8, k + 3, Blocks.stone);
		world.setBlock(i + 9, j + 8, k + 4, Blocks.stone);
		world.setBlock(i + 9, j + 8, k + 5, Blocks.stone);
		world.setBlock(i + 9, j + 8, k + 6, Blocks.stone);
		world.setBlock(i + 9, j + 8, k + 7, Blocks.stone);
		world.setBlock(i + 9, j + 8, k + 8, Blocks.stone);
		world.setBlock(i + 9, j + 8, k + 9, Blocks.stone);
		world.setBlock(i + 9, j + 9, k + 0, Blocks.stone);
		world.setBlock(i + 9, j + 9, k + 1, Blocks.stone);
		world.setBlock(i + 9, j + 9, k + 2, Blocks.stone);
		world.setBlock(i + 9, j + 9, k + 3, Blocks.stone);
		world.setBlock(i + 9, j + 9, k + 4, Blocks.stone);
		world.setBlock(i + 9, j + 9, k + 5, Blocks.stone);
		world.setBlock(i + 9, j + 9, k + 6, Blocks.stone);
		world.setBlock(i + 9, j + 9, k + 7, Blocks.stone);
		world.setBlock(i + 9, j + 9, k + 8, Blocks.stone);
		world.setBlock(i + 9, j + 9, k + 9, Blocks.stone);
		world.setBlock(i + 1, j + 2, k + 4, ChaosBlocks.bedrockWritten);
		world.setBlock(i + 1, j + 2, k + 5, ChaosBlocks.bedrockWritten);
		world.setBlock(i + 1, j + 3, k + 4, ChaosBlocks.bedrockWritten);
		world.setBlock(i + 1, j + 3, k + 5, ChaosBlocks.bedrockWritten);
		world.setBlock(i + 4, j + 2, k + 1, ChaosBlocks.bedrockWritten);
		world.setBlock(i + 4, j + 2, k + 8, ChaosBlocks.bedrockWritten);
		world.setBlock(i + 4, j + 3, k + 1, ChaosBlocks.bedrockWritten);
		world.setBlock(i + 4, j + 3, k + 8, ChaosBlocks.bedrockWritten);
		world.setBlock(i + 5, j + 2, k + 1, ChaosBlocks.bedrockWritten);
		world.setBlock(i + 5, j + 2, k + 8, ChaosBlocks.bedrockWritten);
		world.setBlock(i + 5, j + 3, k + 1, ChaosBlocks.bedrockWritten);
		world.setBlock(i + 5, j + 3, k + 8, ChaosBlocks.bedrockWritten);
		world.setBlock(i + 8, j + 2, k + 4, ChaosBlocks.bedrockWritten);
		world.setBlock(i + 8, j + 2, k + 5, ChaosBlocks.bedrockWritten);
		world.setBlock(i + 8, j + 3, k + 4, ChaosBlocks.bedrockWritten);
		world.setBlock(i + 8, j + 3, k + 5, ChaosBlocks.bedrockWritten);
		return true;
	}
}